Internal Server Error: /api/staff/
Traceback (most recent call last):
  File "D:\projects\Smart-Acess\.venv\lib\site-packages\django\db\backends\utils.py", line 105, in _execute
    return self.cursor.execute(sql, params)
psycopg2.errors.UndefinedTable: relation "staff_staff" does not exist
LINE 1: ...ff"."created_at", "staff_staff"."updated_at" FROM "staff_sta...
                                                             ^


The above exception was the direct cause of the following exception:

Traceback (most recent call last):
  File "D:\projects\Smart-Acess\.venv\lib\site-packages\django\core\handlers\exception.py", line 55, in inner
    response = get_response(request)
  File "D:\projects\Smart-Acess\.venv\lib\site-packages\django\core\handlers\base.py", line 197, in _get_response
    response = wrapped_callback(request, *callback_args, **callback_kwargs)
  File "D:\projects\Smart-Acess\.venv\lib\site-packages\django\views\decorators\csrf.py", line 65, in _view_wrapper
    return view_func(request, *args, **kwargs)
  File "D:\projects\Smart-Acess\.venv\lib\site-packages\rest_framework\viewsets.py", line 125, in view
    return self.dispatch(request, *args, **kwargs)
  File "D:\projects\Smart-Acess\.venv\lib\site-packages\rest_framework\views.py", line 515, in dispatch
    response = self.handle_exception(exc)
  File "D:\projects\Smart-Acess\.venv\lib\site-packages\rest_framework\views.py", line 475, in handle_exception
    self.raise_uncaught_exception(exc)
  File "D:\projects\Smart-Acess\.venv\lib\site-packages\rest_framework\views.py", line 486, in raise_uncaught_exception
    raise exc
  File "D:\projects\Smart-Acess\.venv\lib\site-packages\rest_framework\views.py", line 512, in dispatch
    response = handler(request, *args, **kwargs)
  File "D:\projects\Smart-Acess\backend\staff\views.py", line 53, in list
    response = super().list(request, *args, **kwargs)
  File "D:\projects\Smart-Acess\.venv\lib\site-packages\rest_framework\mixins.py", line 46, in list
    return Response(serializer.data)
  File "D:\projects\Smart-Acess\.venv\lib\site-packages\rest_framework\serializers.py", line 797, in data
    ret = super().data
  File "D:\projects\Smart-Acess\.venv\lib\site-packages\rest_framework\serializers.py", line 251, in data
    self._data = self.to_representation(self.instance)
  File "D:\projects\Smart-Acess\.venv\lib\site-packages\rest_framework\serializers.py", line 715, in to_representation
    return [
  File "D:\projects\Smart-Acess\.venv\lib\site-packages\django\db\models\query.py", line 384, in __iter__
    self._fetch_all()
  File "D:\projects\Smart-Acess\.venv\lib\site-packages\django\db\models\query.py", line 1949, in _fetch_all
    self._result_cache = list(self._iterable_class(self))
  File "D:\projects\Smart-Acess\.venv\lib\site-packages\django\db\models\query.py", line 91, in __iter__
    results = compiler.execute_sql(
  File "D:\projects\Smart-Acess\.venv\lib\site-packages\django\db\models\sql\compiler.py", line 1623, in execute_sql
    cursor.execute(sql, params)
  File "D:\projects\Smart-Acess\.venv\lib\site-packages\django\db\backends\utils.py", line 122, in execute
    return super().execute(sql, params)
  File "D:\projects\Smart-Acess\.venv\lib\site-packages\django\db\backends\utils.py", line 79, in execute
    return self._execute_with_wrappers(
  File "D:\projects\Smart-Acess\.venv\lib\site-packages\django\db\backends\utils.py", line 92, in _execute_with_wrappers
    return executor(sql, params, many, context)
  File "D:\projects\Smart-Acess\.venv\lib\site-packages\django\db\backends\utils.py", line 100, in _execute
    with self.db.wrap_database_errors:
  File "D:\projects\Smart-Acess\.venv\lib\site-packages\django\db\utils.py", line 91, in __exit__
    raise dj_exc_value.with_traceback(traceback) from exc_value
  File "D:\projects\Smart-Acess\.venv\lib\site-packages\django\db\backends\utils.py", line 105, in _execute
    return self.cursor.execute(sql, params)
django.db.utils.ProgrammingError: relation "staff_staff" does not exist
LINE 1: ...ff"."created_at", "staff_staff"."updated_at" FROM "staff_sta...
                                                             ^

[10/Oct/2025 12:14:28] "GET /api/staff/?ordering=-created_at&page=1&page_size=10 HTTP/1.1" 500 24625
Internal Server Error: /api/staff/
Traceback (most recent call last):
  File "D:\projects\Smart-Acess\.venv\lib\site-packages\django\db\backends\utils.py", line 105, in _execute
    return self.cursor.execute(sql, params)
psycopg2.errors.UndefinedTable: relation "staff_staff" does not exist
LINE 1: ...ff"."created_at", "staff_staff"."updated_at" FROM "staff_sta...
                                                             ^


The above exception was the direct cause of the following exception:

Traceback (most recent call last):
  File "D:\projects\Smart-Acess\.venv\lib\site-packages\django\core\handlers\exception.py", line 55, in inner
    response = get_response(request)
  File "D:\projects\Smart-Acess\.venv\lib\site-packages\django\core\handlers\base.py", line 197, in _get_response
    response = wrapped_callback(request, *callback_args, **callback_kwargs)
  File "D:\projects\Smart-Acess\.venv\lib\site-packages\django\views\decorators\csrf.py", line 65, in _view_wrapper
    return view_func(request, *args, **kwargs)
  File "D:\projects\Smart-Acess\.venv\lib\site-packages\rest_framework\viewsets.py", line 125, in view
    return self.dispatch(request, *args, **kwargs)
  File "D:\projects\Smart-Acess\.venv\lib\site-packages\rest_framework\views.py", line 515, in dispatch
    response = self.handle_exception(exc)
  File "D:\projects\Smart-Acess\.venv\lib\site-packages\rest_framework\views.py", line 475, in handle_exception
    self.raise_uncaught_exception(exc)
  File "D:\projects\Smart-Acess\.venv\lib\site-packages\rest_framework\views.py", line 486, in raise_uncaught_exception
    raise exc
  File "D:\projects\Smart-Acess\.venv\lib\site-packages\rest_framework\views.py", line 512, in dispatch
    response = handler(request, *args, **kwargs)
  File "D:\projects\Smart-Acess\backend\staff\views.py", line 53, in list
    response = super().list(request, *args, **kwargs)
  File "D:\projects\Smart-Acess\.venv\lib\site-packages\rest_framework\mixins.py", line 46, in list
    return Response(serializer.data)
  File "D:\projects\Smart-Acess\.venv\lib\site-packages\rest_framework\serializers.py", line 797, in data
    ret = super().data
  File "D:\projects\Smart-Acess\.venv\lib\site-packages\rest_framework\serializers.py", line 251, in data
    self._data = self.to_representation(self.instance)
  File "D:\projects\Smart-Acess\.venv\lib\site-packages\rest_framework\serializers.py", line 715, in to_representation
    return [
  File "D:\projects\Smart-Acess\.venv\lib\site-packages\django\db\models\query.py", line 384, in __iter__
    self._fetch_all()
  File "D:\projects\Smart-Acess\.venv\lib\site-packages\django\db\models\query.py", line 1949, in _fetch_all
    self._result_cache = list(self._iterable_class(self))
  File "D:\projects\Smart-Acess\.venv\lib\site-packages\django\db\models\query.py", line 91, in __iter__
    results = compiler.execute_sql(
  File "D:\projects\Smart-Acess\.venv\lib\site-packages\django\db\models\sql\compiler.py", line 1623, in execute_sql
    cursor.execute(sql, params)
  File "D:\projects\Smart-Acess\.venv\lib\site-packages\django\db\backends\utils.py", line 122, in execute
    return super().execute(sql, params)
  File "D:\projects\Smart-Acess\.venv\lib\site-packages\django\db\backends\utils.py", line 79, in execute
    return self._execute_with_wrappers(
  File "D:\projects\Smart-Acess\.venv\lib\site-packages\django\db\backends\utils.py", line 92, in _execute_with_wrappers
    return executor(sql, params, many, context)
  File "D:\projects\Smart-Acess\.venv\lib\site-packages\django\db\backends\utils.py", line 100, in _execute
    with self.db.wrap_database_errors:
  File "D:\projects\Smart-Acess\.venv\lib\site-packages\django\db\utils.py", line 91, in __exit__
    raise dj_exc_value.with_traceback(traceback) from exc_value
  File "D:\projects\Smart-Acess\.venv\lib\site-packages\django\db\backends\utils.py", line 105, in _execute
    return self.cursor.execute(sql, params)
django.db.utils.ProgrammingError: relation "staff_staff" does not exist
LINE 1: ...ff"."created_at", "staff_staff"."updated_at" FROM "staff_sta...
                                                             ^

[10/Oct/2025 12:14:28] "GET /api/staff/?ordering=-created_at&page=1&page_size=10 HTTP/1.1" 500 24625
[10/Oct/2025 12:15:18] "GET /api/staff/validation-info/ HTTP/1.1" 200 812
[10/Oct/2025 12:15:18] "GET /api/staff/validation-info/ HTTP/1.1" 200 812
